wandb: Streaming LlamaIndex events to W&B at https://wandb.ai/arunk777/gemini-test/runs/cnbver0n
wandb: `WandbCallbackHandler` is currently in beta.
wandb: Please report any issues to https://github.com/wandb/wandb/issues with the tag `llamaindex`.
[nltk_data] Downloading package punkt to /Users/asanthan/nltk_data...
[nltk_data]   Package punkt is already up-to-date!
[nltk_data] Downloading package averaged_perceptron_tagger to
[nltk_data]     /Users/asanthan/nltk_data...
[nltk_data]   Package averaged_perceptron_tagger is already up-to-
[nltk_data]       date!
Parsing nodes: 100%|██████████| 1/1 [00:00<00:00,  5.20it/s]

100%|██████████| 8/8 [00:03<00:00,  2.07it/s]
100%|██████████| 2/2 [00:01<00:00,  1.62it/s]
100%|██████████| 2/2 [00:01<00:00,  1.77it/s]
100%|██████████| 2/2 [00:01<00:00,  1.97it/s]
100%|██████████| 2/2 [00:01<00:00,  1.84it/s]
100%|██████████| 2/2 [00:01<00:00,  1.16it/s]
100%|██████████| 2/2 [00:01<00:00,  1.64it/s]
100%|██████████| 2/2 [00:01<00:00,  1.76it/s]

100%|██████████| 2/2 [00:01<00:00,  1.15it/s]
Traceback (most recent call last):
  File "/Users/asanthan/work/development/greenfield/demos/generative-ai/RAG/utils/evaluation/rag_evaluation.py", line 178, in <module>
    loop = asyncio.run(batch())
  File "/Users/asanthan/.pyenv/versions/3.10.10/lib/python3.10/asyncio/runners.py", line 44, in run
    return loop.run_until_complete(main)
  File "/Users/asanthan/.pyenv/versions/3.10.10/lib/python3.10/asyncio/base_events.py", line 649, in run_until_complete
    return future.result()
  File "/Users/asanthan/work/development/greenfield/demos/generative-ai/RAG/utils/evaluation/rag_evaluation.py", line 131, in batch
    result = evaluate(query_engine, metrics, eval_questions, eval_answers)
  File "/Users/asanthan/work/development/greenfield/demos/generative-ai/RAG/venv/lib/python3.10/site-packages/ragas/llama_index/evaluation.py", line 99, in evaluate
    result = ragas_evaluate(ds, metrics)
  File "/Users/asanthan/work/development/greenfield/demos/generative-ai/RAG/venv/lib/python3.10/site-packages/ragas/evaluation.py", line 89, in evaluate
    validate_column_dtypes(dataset)
  File "/Users/asanthan/work/development/greenfield/demos/generative-ai/RAG/venv/lib/python3.10/site-packages/ragas/validation.py", line 31, in validate_column_dtypes
    raise ValueError(
ValueError: Dataset feature "contexts" should be of type Sequence[string], got <class 'datasets.features.features.Sequence'>