wandb: Streaming LlamaIndex events to W&B at https://wandb.ai/arunk777/gemini-test/runs/0dljul3d
wandb: `WandbCallbackHandler` is currently in beta.
wandb: Please report any issues to https://github.com/wandb/wandb/issues with the tag `llamaindex`.
[nltk_data] Downloading package punkt to /Users/asanthan/nltk_data...
[nltk_data]   Package punkt is already up-to-date!
[nltk_data] Downloading package averaged_perceptron_tagger to
[nltk_data]     /Users/asanthan/nltk_data...
[nltk_data]   Package averaged_perceptron_tagger is already up-to-
[nltk_data]       date!
Parsing nodes: 100%|██████████| 1/1 [00:00<00:00, 60.98it/s]

100%|██████████| 8/8 [00:04<00:00,  1.90it/s]
100%|██████████| 2/2 [00:01<00:00,  1.13it/s]
100%|██████████| 2/2 [00:01<00:00,  1.83it/s]
100%|██████████| 2/2 [00:02<00:00,  1.11s/it]
100%|██████████| 2/2 [00:05<00:00,  2.91s/it]
100%|██████████| 2/2 [00:01<00:00,  1.04it/s]
100%|██████████| 2/2 [00:01<00:00,  1.99it/s]
100%|██████████| 2/2 [00:00<00:00,  2.64it/s]
100%|██████████| 2/2 [00:01<00:00,  1.85it/s]
What is the purpose of the Power Interface Module (PIM) in the ArmorKinetix system?
Traceback (most recent call last):
  File "/Users/asanthan/work/development/greenfield/demos/generative-ai/RAG/venv/lib/python3.10/site-packages/google/api_core/grpc_helpers.py", line 79, in error_remapped_callable
    return callable_(*args, **kwargs)
  File "/Users/asanthan/work/development/greenfield/demos/generative-ai/RAG/venv/lib/python3.10/site-packages/grpc/_channel.py", line 1160, in __call__
    return _end_unary_response_blocking(state, call, False, None)
  File "/Users/asanthan/work/development/greenfield/demos/generative-ai/RAG/venv/lib/python3.10/site-packages/grpc/_channel.py", line 1003, in _end_unary_response_blocking
    raise _InactiveRpcError(state)  # pytype: disable=not-instantiable
grpc._channel._InactiveRpcError: <_InactiveRpcError of RPC that terminated with:
	status = StatusCode.PERMISSION_DENIED
	details = "Request had insufficient authentication scopes."
	debug_error_string = "UNKNOWN:Error received from peer ipv4:172.217.0.170:443 {grpc_message:"Request had insufficient authentication scopes.", grpc_status:7, created_time:"2024-02-05T08:27:33.760048-06:00"}"
>
The above exception was the direct cause of the following exception:
Traceback (most recent call last):
  File "/Users/asanthan/work/development/greenfield/demos/generative-ai/RAG/utils/evaluation/rag_evaluation.py", line 122, in <module>
    loop = asyncio.run(batch())
  File "/Users/asanthan/.pyenv/versions/3.10.10/lib/python3.10/asyncio/runners.py", line 44, in run
    return loop.run_until_complete(main)
  File "/Users/asanthan/.pyenv/versions/3.10.10/lib/python3.10/asyncio/base_events.py", line 649, in run_until_complete
    return future.result()
  File "/Users/asanthan/work/development/greenfield/demos/generative-ai/RAG/utils/evaluation/rag_evaluation.py", line 103, in batch
    response = query_engine.query(rag_dataset.examples[0].query)
  File "/Users/asanthan/work/development/greenfield/demos/generative-ai/RAG/venv/lib/python3.10/site-packages/llama_index/core/base_query_engine.py", line 40, in query
    return self._query(str_or_query_bundle)
  File "/Users/asanthan/work/development/greenfield/demos/generative-ai/RAG/venv/lib/python3.10/site-packages/llama_index/query_engine/retriever_query_engine.py", line 171, in _query
    nodes = self.retrieve(query_bundle)
  File "/Users/asanthan/work/development/greenfield/demos/generative-ai/RAG/venv/lib/python3.10/site-packages/llama_index/query_engine/retriever_query_engine.py", line 127, in retrieve
    nodes = self._retriever.retrieve(query_bundle)
  File "/Users/asanthan/work/development/greenfield/demos/generative-ai/RAG/venv/lib/python3.10/site-packages/llama_index/core/base_retriever.py", line 224, in retrieve
    nodes = self._retrieve(query_bundle)
  File "/Users/asanthan/work/development/greenfield/demos/generative-ai/RAG/venv/lib/python3.10/site-packages/llama_index/indices/vector_store/retrievers/retriever.py", line 88, in _retrieve
    self._service_context.embed_model.get_agg_embedding_from_queries(
  File "/Users/asanthan/work/development/greenfield/demos/generative-ai/RAG/venv/lib/python3.10/site-packages/llama_index/core/embeddings/base.py", line 142, in get_agg_embedding_from_queries
    query_embeddings = [self.get_query_embedding(query) for query in queries]
  File "/Users/asanthan/work/development/greenfield/demos/generative-ai/RAG/venv/lib/python3.10/site-packages/llama_index/core/embeddings/base.py", line 142, in <listcomp>
    query_embeddings = [self.get_query_embedding(query) for query in queries]
  File "/Users/asanthan/work/development/greenfield/demos/generative-ai/RAG/venv/lib/python3.10/site-packages/llama_index/core/embeddings/base.py", line 111, in get_query_embedding
    query_embedding = self._get_query_embedding(query)
  File "/Users/asanthan/work/development/greenfield/demos/generative-ai/RAG/venv/lib/python3.10/site-packages/llama_index/embeddings/google_palm.py", line 53, in _get_query_embedding
    return self._model.generate_embeddings(model=self.model_name, text=query)[
  File "/Users/asanthan/work/development/greenfield/demos/generative-ai/RAG/venv/lib/python3.10/site-packages/google/generativeai/text.py", line 304, in generate_embeddings
    embedding_response = client.embed_text(embedding_request)
  File "/Users/asanthan/work/development/greenfield/demos/generative-ai/RAG/venv/lib/python3.10/site-packages/google/ai/generativelanguage_v1beta/services/text_service/client.py", line 760, in embed_text
    response = rpc(
  File "/Users/asanthan/work/development/greenfield/demos/generative-ai/RAG/venv/lib/python3.10/site-packages/google/api_core/gapic_v1/method.py", line 131, in __call__
    return wrapped_func(*args, **kwargs)
  File "/Users/asanthan/work/development/greenfield/demos/generative-ai/RAG/venv/lib/python3.10/site-packages/google/api_core/retry.py", line 372, in retry_wrapped_func
    return retry_target(
  File "/Users/asanthan/work/development/greenfield/demos/generative-ai/RAG/venv/lib/python3.10/site-packages/google/api_core/retry.py", line 207, in retry_target
    result = target()
  File "/Users/asanthan/work/development/greenfield/demos/generative-ai/RAG/venv/lib/python3.10/site-packages/google/api_core/timeout.py", line 120, in func_with_timeout
    return func(*args, **kwargs)
  File "/Users/asanthan/work/development/greenfield/demos/generative-ai/RAG/venv/lib/python3.10/site-packages/google/api_core/grpc_helpers.py", line 81, in error_remapped_callable
    raise exceptions.from_grpc_error(exc) from exc
google.api_core.exceptions.PermissionDenied: 403 Request had insufficient authentication scopes. [reason: "ACCESS_TOKEN_SCOPE_INSUFFICIENT"
domain: "googleapis.com"
metadata {
  key: "service"
  value: "generativelanguage.googleapis.com"
}
metadata {
  key: "method"
  value: "google.ai.generativelanguage.v1beta.TextService.EmbedText"
}
]